Workbook

Sheet Export Summary
B3: This document was exported from Numbers. Each table was converted to an Excel worksheet. All other objects on each Numbers sheet were placed on separate worksheets. Please be aware that formula calculations may differ in Excel.
B7: Numbers Sheet Name | C7: Numbers Table Name | D7: Excel Worksheet Name
B9: presupuesto
C10: Gastos | D10: presupuesto - Gastos
C11: Table 2 | D11: presupuesto - Table 2
C12: Table 1 | D12: presupuesto - Table 1
C13: Table 3 | D13: presupuesto - Table 3
C14: Ingreso líquido | D14: presupuesto - Ingreso líquido
C15: Capacidad ahorro | D15: presupuesto - Capacidad ahorro
C16: APV - simulación régimen B | D16: presupuesto - APV - simulación
C17: apv - rebaja impuestos interés hipotecario | D17: presupuesto - apv - rebaja impu
B18: flujos
C19: Gasto mes actual | D19: flujos - Gasto mes actual
C20: Table 1-3 | D20: flujos - Table 1-3
C21: Table 1-2 | D21: flujos - Table 1-2
C22: Table 1-4 | D22: flujos - Table 1-4
C23: Table 3-1-1 | D23: flujos - Table 3-1-1
C24: Table 3-1-1-1 | D24: flujos - Table 3-1-1-1
C25: Table 3-1 | D25: flujos - Table 3-1
C26: Totales | D26: flujos - Totales
C27: Table 2-1 | D27: flujos - Table 2-1
C28: Table 3-2 | D28: flujos - Table 3-2
C29: Gasto mensual | D29: flujos - Gasto mensual
C30: Table 1 | D30: flujos - Table 1
... C37: “All Drawings from the Sheet” | D37: flujos - Drawings
B38: anual
C39: Table 1-1 | D39: anual - Table 1-1
B40: net worth
C41: Table 2 | D41: net worth - Table 2
C42: dap-1 | D42: net worth - dap-1
C43: net worth | D43: net worth - net worth
C44: cash | D44: net worth - cash
C45: balances | D45: net worth - balances
C46: Table 1 | D46: net worth - Table 1
C47: resumen | depósitos - actual | D47: net worth - resumen | depósitos
C48: retiro | D48: net worth - retiro
C49: brokerage | D49: net worth - brokerage
C50: cash and cash equivalents | D50: net worth - cash and cash equiv
C51: criptomonedas | D51: net worth - criptomonedas
C52: Aporte APV | D52: net worth - Aporte APV
...

Sheet presupuesto - Gastos
E1: CLP
A2: Credito hipotecario | B2: TRUE | C2: {=IF(B2,E2/'presupuesto - Ingreso líquido'!$B$31,0)} -> 0.52205009 | D2: {=IF(B2,E2/'presupuesto - Ingreso líquido'!$B$32,0)} -> 0.63278043 | E2: 2000000 | F2: {=SUMIF(B2:B4,"=TRUE",E2:E4)} -> 2230990 | G2: {=IF(F2,F2/'presupuesto - Ingreso líquido'!$B$31,0)} -> 0.58234426 | H2: Internet | I2: 20990
A3: Arriendo | B3: FALSE | C3: {=IF(B3,E3/'presupuesto - Ingreso líquido'!$B$31,0)} -> 0 | D3: {=IF(B3,E3/'presupuesto - Ingreso líquido'!$B$32,0)} -> 0 | E3: - | F3: 18 | G3: {=IF(F2,F2/'presupuesto - Ingreso líquido'!$B$32,0)} -> 0.70586341 | H3: Agua | I3: -
A4: Cuentas | B4: TRUE | C4: {=IF(B4,E4/'presupuesto - Ingreso líquido'!$B$31,0)} -> 0.060294175 | D4: {=IF(B4,E4/'presupuesto - Ingreso líquido'!$B$32,0)} -> 0.073082976 | E4: {=SUM(I2:I7)} -> 230990 | H4: Luz | I4: 40000
C5: {=IF(B5,E5/'presupuesto - Ingreso líquido'!$B$31,0)} -> 0 | D5: {=IF(B5,E5/'presupuesto - Ingreso líquido'!$B$32,0)} -> 0 | H5: Gas | I5: 30000
A6: Supermercado | B6: TRUE | C6: {=IF(B6,E6/'presupuesto - Ingreso líquido'!$B$31,0)} -> 0.039153756 | D6: {=IF(B6,E6/'presupuesto - Ingreso líquido'!$B$32,0)} -> 0.047458532 | E6: {=150000} -> 150000 | H6: Gastos comunes | I6: 90000
C7: {=IF(B7,E7/'presupuesto - Ingreso líquido'!$B$31,0)} -> 0 | D7: {=IF(B7,E7/'presupuesto - Ingreso líquido'!$B$32,0)} -> 0 | H7: Estacionamiento | I7: 50000
A8: Celular | B8: FALSE | C8: {=IF(B8,E8/'presupuesto - Ingreso líquido'!$B$31,0)} -> 0 | D8: {=IF(B8,E8/'presupuesto - Ingreso líquido'!$B$32,0)} -> 0 | E8: 20000
A9: Bip | B9: FALSE | C9: {=IF(B9,E9/'presupuesto - Ingreso líquido'!$B$31,0)} -> 0 | D9: {=IF(B9,E9/'presupuesto - Ingreso líquido'!$B$32,0)} -> 0 | E9: 5000 | H9: Arriendo máximo | I9: {='presupuesto - Ingreso líquido'!B32*30%} -> 948196.2
A10: Uber | B10: FALSE | C10: {=IF(B10,E10/'presupuesto - Ingreso líquido'!$B$31,0)} -> 0 | D10: {=IF(B10,E10/'presupuesto - Ingreso líquido'!$B$32,0)} -> 0 | E10: 10000 | I10: {='presupuesto - Ingreso líquido'!B32/3} -> 1053551.3
A11: Suscripciones | B11: TRUE | C11: {=IF(B11,E11/'presupuesto - Ingreso líquido'!$B$31,0)} -> 0.0020278383 | D11: {=IF(B11,E11/'presupuesto - Ingreso líquido'!$B$32,0)} -> 0.0024579565 | E11: {=SUMIF('presupuesto - Table 2'!B2:B13,"=TRUE",'presupuesto - Table 2'!C2:C13)} -> 7768.75 | I11: {='presupuesto - Ingreso líquido'!B31*30%} -> 1149315
A12: Gimnasio | B12: FALSE | C12: {=IF(B12,E12/'presupuesto - Ingreso líquido'!$B$31,0)} -> 0 | D12: {=IF(B12,E12/'presupuesto - Ingreso líquido'!$B$32,0)} -> 0 | E12: 15000 | H12: Sueldo liq ideal | I12: {=SUM(E3:E4)/30%} -> 769966.67
B13: FALSE | C13: {=IF(B13,E13/'presupuesto - Ingreso líquido'!$B$31,0)} -> 0 | D13: {=IF(B13,E13/'presupuesto - Ingreso líquido'!$B$32,0)} -> 0 | I13: {=I12-'presupuesto - Ingreso líquido'!B32} -> -2390687.3
A14: Salud | B14: FALSE | C14: {=IF(B14,E14/'presupuesto - Ingreso líquido'!$B$31,0)} -> 0 | D14: {=IF(B14,E14/'presupuesto - Ingreso líquido'!$B$32,0)} -> 0 | E14: 50000
A15: Isapre | B15: TRUE | C15: {=IF(B15,E15/'presupuesto - Ingreso líquido'!$B$31,0)} -> 0.066782474 | D15: {=IF(B15,E15/'presupuesto - Ingreso líquido'!$B$32,0)} -> 0.080947487 | E15: {='presupuesto - Ingreso líquido'!B18} -> 255847
B16: FALSE | C16: {=IF(B16,E16/'presupuesto - Ingreso líquido'!$B$31,0)} -> 0 | D16: {=IF(B16,E16/'presupuesto - Ingreso líquido'!$B$32,0)} -> 0
B17: FALSE | C17: {=IF(B17,E17/'presupuesto - Ingreso líquido'!$B$31,0)} -> 0 | D17: {=IF(B17,E17/'presupuesto - Ingreso líquido'!$B$32,0)} -> 0
A18: Estacionamiento | B18: FALSE | C18: {=IF(B18,E18/'presupuesto - Ingreso líquido'!$B$31,0)} -> 0 | D18: {=IF(B18,E18/'presupuesto - Ingreso líquido'!$B$32,0)} -> 0 | E18: {=F18*'variables - Table 1'!B2} -> 119801.54 | F18: 2.95 | I18: Marzo auto
A19: Estacionar casual | B19: FALSE | C19: {=IF(B19,E19/'presupuesto - Ingreso líquido'!$B$31,0)} -> 0 | D19: {=IF(B19,E19/'presupuesto - Ingreso líquido'!$B$32,0)} -> 0 | E19: 5000 | H19: SOAP | I19: 5000
A20: Mantencion | B20: TRUE | C20: {=IF(B20,E20/'presupuesto - Ingreso líquido'!$B$31,0)} -> 0.0065256261 | D20: {=IF(B20,E20/'presupuesto - Ingreso líquido'!$B$32,0)} -> 0.0079097554 | E20: 25000 | H20: Patente | I20: 221288
A21: Bencina | B21: TRUE | C21: {=IF(B21,E21/'presupuesto - Ingreso líquido'!$B$31,0)} -> 0.0078307513 | D21: {=IF(B21,E21/'presupuesto - Ingreso líquido'!$B$32,0)} -> 0.0094917065 | E21: 30000 | H21: Revisión técnica | I21: 20000
A22: Seguro auto | B22: FALSE | C22: {=IF(B22,E22/'presupuesto - Ingreso líquido'!$B$31,0)} -> 0 | D22: {=IF(B22,E22/'presupuesto - Ingreso líquido'!$B$32,0)} -> 0 | E22: {=515577/12} -> 42964.75 | F22: {=SUM(E18:E24)} -> 248290.29 | I22: {=SUM(I19:I21)} -> 246288
A23: Marzo / 12 | B23: TRUE | C23: {=IF(B23,E23/'presupuesto - Ingreso líquido'!$B$31,0)} -> 0.005357278 | D23: {=IF(B23,E23/'presupuesto - Ingreso líquido'!$B$32,0)} -> 0.0064935928 | E23: {=I23} -> 20524 | F23: {=F24*12} -> 906288 | H23: Por mes | I23: {=I22/12} -> 20524
A24: Tag | B24: FALSE | C24: {=IF(B24,E24/'presupuesto - Ingreso líquido'!$B$31,0)} -> 0 | D24: {=IF(B24,E24/'presupuesto - Ingreso líquido'!$B$32,0)} -> 0 | E24: 5000 | F24: {=SUMIF(B18:B24,"=TRUE",E18:E24)} -> 75524 | G24: {=IF(F24,F24/'presupuesto - Ingreso líquido'!$B$31,0)} -> 0.019713655
B25: FALSE | C25: {=IF(B25,E25/'presupuesto - Ingreso líquido'!$B$31,0)} -> 0 | D25: {=IF(B25,E25/'presupuesto - Ingreso líquido'!$B$32,0)} -> 0
A26: take out | B26: TRUE | C26: {=IF(B26,E26/'presupuesto - Ingreso líquido'!$B$31,0)} -> 0.026102504 | D26: {=IF(B26,E26/'presupuesto - Ingreso líquido'!$B$32,0)} -> 0.031639022 | E26: 100000
A27: Carrete | B27: TRUE | C27: {=IF(B27,E27/'presupuesto - Ingreso líquido'!$B$31,0)} -> 0.026102504 | D27: {=IF(B27,E27/'presupuesto - Ingreso líquido'!$B$32,0)} -> 0.031639022 | E27: 100000
A28: Fun | B28: TRUE | C28: {=IF(B28,E28/'presupuesto - Ingreso líquido'!$B$31,0)} -> 0.031323005 | D28: {=IF(B28,E28/'presupuesto - Ingreso líquido'!$B$32,0)} -> 0.037966826 | E28: 120000
A29: Drugs | B29: TRUE | C29: {=IF(B29,E29/'presupuesto - Ingreso líquido'!$B$31,0)} -> 0.052205009 | D29: {=IF(B29,E29/'presupuesto - Ingreso líquido'!$B$32,0)} -> 0.063278043 | E29: 200000
B30: FALSE | C30: {=IF(B30,E30/'presupuesto - Ingreso líquido'!$B$31,0)} -> 0 | D30: {=IF(B30,E30/'presupuesto - Ingreso líquido'!$B$32,0)} -> 0
A31: Limpieza | B31: FALSE | C31: {=IF(B31,E31/'presupuesto - Ingreso líquido'!$B$31,0)} -> 0 | D31: {=IF(B31,E31/'presupuesto - Ingreso líquido'!$B$32,0)} -> 0
A32: Lavanderia | B32: FALSE | C32: {=IF(B32,E32/'presupuesto - Ingreso líquido'!$B$31,0)} -> 0 | D32: {=IF(B32,E32/'presupuesto - Ingreso líquido'!$B$32,0)} -> 0
A33: Shit | B33: TRUE | C33: {=IF(B33,E33/'presupuesto - Ingreso líquido'!$B$31,0)} -> 0.031323005 | D33: {=IF(B33,E33/'presupuesto - Ingreso líquido'!$B$32,0)} -> 0.037966826 | E33: 120000
A34: Gasto mensual | C34: {=$E34/'presupuesto - Ingreso líquido'!$B$35} -> 1.0631122 | E34: {=SUMIF(B2:B33,"=TRUE",E2:E33)} -> 3360129.8 | F34: {=E$34/'variables - Table 1'!$B$5} -> 3481.9997 | H34: Gasto anual | I34: Ahorro anual
A35: Disponible | C35: {=$E35/'presupuesto - Ingreso líquido'!$B$35} -> 0.14899457 | E35: {='presupuesto - Ingreso líquido'!B31-E$34} -> 470920.29 | F35: {=E$35/'variables - Table 1'!$B$5} -> 488.0003 | H35: {=E$34*12} -> 40321557 | I35: {=E$35*12} -> 5651043.5
A36: Disponible liq | C36: {=$E36/'presupuesto - Ingreso líquido'!$B$35} -> -0.063112176 | E36: {='presupuesto - Ingreso líquido'!B32-E$34} -> -199475.75 | H36: {=H$35/'variables - Table 1'!$B$5} -> 41783.997 | I36: {=I$35/'variables - Table 1'!$B$5} -> 5856.0036
H37: Tasa de ahorro | I37: {=E$35/'presupuesto - Ingreso líquido'!B31} -> 0.12292199

Sheet presupuesto - Table 2
A1: Suscripciones
A2: Netflix | B2: FALSE | C2: 7390
A3: Apple Music | B3: TRUE | C3: 3500
A4: iCloud | B4: TRUE | C4: 650
A5: apple tv+ | B5: TRUE
A6: paramount+ | B6: TRUE
B7: FALSE
A8: uber one | B8: FALSE | C8: 5000
A9: 1password | B9: TRUE | C9: {='variables - Table 1'!B5*D9} -> 3618.75 | D9: {=45/12} -> 3.75
B10: FALSE
B11: FALSE
B12: FALSE
B13: FALSE

Sheet presupuesto - Table 1
A1: Wishlist | B1: Chile | D1: {=SUM(D2:D21)} -> 3179.99 | E1: {=SUM(E2:E21)} -> 3360215.9 | F1: Diferencia
A2: iPhone SE2 128 GB | B2: FALSE | C2: 450000 | D2: 449 | E2: {=D2*1.095*'variables - Table 1'!$B$5} -> 474447.08 | F2: {=C2-E2} -> -24447.075
A3: Mac Mini | B3: FALSE | C3: 999990 | D3: 999 | E3: {=D3*1.095*'variables - Table 1'!$B$5} -> 1055618.3 | F3: {=C3-E3} -> -55628.325
A4: Volcano digital | B4: TRUE | C4: 379000 | D4: 599 | E4: {=D4*1.095*'variables - Table 1'!$B$5} -> 632948.32 | F4: {=C4-E4} -> -253948.33
A5: Pax 3 | B5: FALSE | C5: 299990 | D5: 274.99 | E5: {=D5*1.095*'variables - Table 1'!$B$5} -> 290575.06 | F5: {=C5-E5} -> 9414.9417
A6: MFLB | B6: TRUE | C6: 95000 | D6: 129 | E6: {=D6*1.095*'variables - Table 1'!$B$5} -> 136311.08 | F6: {=C6-E6} -> -41311.075
A7: Bongs | B7: FALSE
A8: DaVinci IQ | B8: TRUE | C8: 210000 | D8: 200 | E8: {=D8*1.095*'variables - Table 1'!$B$5} -> 211335 | F8: {=C8-E8} -> -1335
B9: FALSE
A10: Barbour Ashby Waxed Jacket | B10: FALSE
B11: FALSE
A12: Escritorio | B12: TRUE | C12: 100000
A13: Silla | B13: TRUE | C13: 50000
A14: Pantalla | B14: TRUE | C14: 160000
A15: Repuestos PC | B15: TRUE | C15: 160000
A16: tv | B16: FALSE | C16: 179990 | D16: 179 | E16: {=D16*1.095*'variables - Table 1'!$B$5} -> 189144.83 | F16: {=C16-E16} -> -9154.825
B17: FALSE
B18: FALSE
B19: FALSE
A20: Sony 1000XM3 | B20: FALSE | C20: 250000 | D20: 350 | E20: {=D20*1.095*'variables - Table 1'!$B$5} -> 369836.25 | F20: {=C20-E20} -> -119836.25
B21: FALSE
A22: {=SUM(C$22:E$22)} -> 3533621.5 | C22: {=SUMIF(B2:B21,"=TRUE",C2:C21)} -> 1154000 | E22: {=SUMIF(B2:B21,"=FALSE",E2:E21)} -> 2379621.5

Sheet presupuesto - Table 3
A1: Ahorro | B1: Mensual | C1: Anual
A2: Fintual | B2: 400000 | C2: {=B2*12} -> 4800000
A3: AFP | B3: {='presupuesto - Ingreso líquido'!B17} -> 365496 | C3: {=B3*12} -> 4385952
A4: APV - a | B4: {='presupuesto - APV - simulación '!B$14} -> 240627 | C4: {=B4*12} -> 2887524
A5: APV - b | B5: {=200000*0} -> 0 | C5: {=B5*12} -> 0
A6: Ahorro vivienda | B6: 250000 | C6: {=B6*12} -> 3000000
A9: Ahorro | B9: {=SUM(B2:B8)} -> 1256123
A10: Sobra | B10: {='presupuesto - Gastos'!E$35-B$9} -> -785202.71

Sheet presupuesto - Ingreso líquido
A1: Ingreso líquido
A3: Sueldo base | B3: {=3640000+14668+37770} -> 3692438
B4: {=B3/4} -> 923109.5
A5: sueldo min × 4,75÷12 | B5: {=MIN('variables - Table 1'!B8*4.75/12)} -> 213354.17 | D5: Tope 2026
A6: Gratificación | B6: {=ROUND(MIN('variables - Table 1'!B8*4.75/12,B3/4),0)} -> 213354 | C6: previsional | D6: 90
D7: {=ROUND(D6*'variables - Table 1'!$B$2,0)} -> 3654962
A8: Movilización | B8: {=19000*1} -> 19000 | C8: cesantía | D8: 135.2
A9: Colación | B9: {=57000*1} -> 57000 | D9: {=ROUND(D8*'variables - Table 1'!$B$2,0)} -> 5490565
A11: Total sueldo bruto | B11: {=B3+B6+B8+B9} -> 3981792 | C11: {=B11/'variables - Table 1'!B$13} -> 4489.3589
A12: Sueldo imponible | B12: {=SUM(B3,B6)} -> 3905792
A13: Base imponible | B13: {=ROUND(MIN(B12,D6*'variables - Table 1'!B2),0)} -> 3654962
D14: {=D15/'variables - Table 1'!B13} -> 4945.038
A15: AFP | B15: {=SUM(B16:B17)} -> 382309 | C15: Anual AFP | D15: {=B17*12} -> 4385952
A16: Comision | B16: {=ROUND(B13*D16%,0)} -> 16813 | C16: Comisión AFP | D16: 0.46
A17: AFP depositado | B17: {=ROUND(B13*10%,0)} -> 365496
A18: Previsión 7% | B18: {=ROUND(B13*7%,0)} -> 255847 | C18: {=B18/'variables - Table 1'!B2} -> 6.2999915 | D18: 4.91
C19: Isapre | D19: {=ROUND(D18*'variables - Table 1'!B2,0)} -> 199398
A20: Seguro de cesantía | B20: {=ROUND(MIN(B12,D9)*0.6%,0)} -> 23435 | C20: Excedentes | D20: {=B18-D19} -> 56449
A21: + empleador | B21: {=ROUND(MIN(B12,D9)*1.6%,0)} -> 62493 | C21: Anuales | D21: {=D20*12} -> 677388
D22: {=D21/D19} -> 3.3971655
A24: Base tributable | B24: {=B12-(B15+B18+B20)} -> 3244201
A26: Impuesto efectivo | B26: {='presupuesto - APV - simulación '!H$11} -> 133928.96 | C26: {=ROUND(B26/B11*100,0)%} -> 0.03
C27: Anual impuestos | D27: {=B26*12} -> 1607147.5
A28: Seguro colectivo | B28: 25618
A29: Total descuentos | B29: {=ROUND(B26+B20+B15+B18+B28,0)} -> 821138 | C29: {=ROUND(B29/B11*100,0)%} -> 0.21
A31: Sin impuestos | B31: {=B11-B26-B16} -> 3831050 | C31: {=B31/'variables - Table 1'!B$13} -> 4319.4016 | D31: {=B31/'variables - Table 1'!$B$14} -> 3685.1548
A32: Sueldo líquido | B32: {=B11-B29} -> 3160654 | C32: {=B32/'variables - Table 1'!B$13} -> 3563.5488 | D32: {=B32/'variables - Table 1'!$B$14} -> 3040.289
A33: Dealing | B33: 0
A35: Ingreso líquido | B35: {=SUM(B32:B33)} -> 3160654
A37: Anual tributable | B37: {=B24*12} -> 38930412
A38: Anual líquido | B38: {=B35*12} -> 37927848 | C38: {=B38/'variables - Table 1'!B$13} -> 42762.586 | D38: {=B38/'variables - Table 1'!$B$14} -> 36483.468
B39: {=(B31)*12} -> 45972600 | C39: {=B39/'variables - Table 1'!B$13} -> 51832.819 | D39: {=B39/'variables - Table 1'!$B$14} -> 44221.857
A40: Anual bruto | B40: {=B11*12} -> 47781504 | C40: {=B40/'variables - Table 1'!B$13} -> 53872.307 | D40: {=B40/'variables - Table 1'!$B$14} -> 45961.873

Sheet presupuesto - Capacidad ahorro
A1: Capacidad ahorro
A2: Meses: | B2: 1 | C2: 3 | D2: 6 | E2: 12 | F2: 18 | G2: 24
A3: 0.1 | B3: {='presupuesto - Ingreso líquido'!$B$31*$A3*B$2} -> 383105 | C3: {=$B3*C$2} -> 1149315 | D3: {=$B3*D$2} -> 2298630 | E3: {=$B3*E$2} -> 4597260 | F3: {=$B3*F$2} -> 6895890.1 | G3: {=$B3*G$2} -> 9194520.1
A4: 0.2 | B4: {='presupuesto - Ingreso líquido'!$B$31*$A4*B$2} -> 766210.01 | C4: {=$B4*C$2} -> 2298630 | D4: {=$B4*D$2} -> 4597260 | E4: {=$B4*E$2} -> 9194520.1 | F4: {=$B4*F$2} -> 13791780 | G4: {=$B4*G$2} -> 18389040
A5: 0.5 | B5: {='presupuesto - Ingreso líquido'!$B$31*$A5*B$2} -> 1915525 | C5: {=$B5*C$2} -> 5746575.1 | D5: {=$B5*D$2} -> 11493150 | E5: {=$B5*E$2} -> 22986300 | F5: {=$B5*F$2} -> 34479450 | G5: {=$B5*G$2} -> 45972600
A6: 0.6 | B6: {='presupuesto - Ingreso líquido'!$B$31*$A6*B$2} -> 2298630 | C6: {=$B6*C$2} -> 6895890.1 | D6: {=$B6*D$2} -> 13791780 | E6: {=$B6*E$2} -> 27583560 | F6: {=$B6*F$2} -> 41375340 | G6: {=$B6*G$2} -> 55167121
A7: 0.7 | B7: {='presupuesto - Ingreso líquido'!$B$31*$A7*B$2} -> 2681735 | C7: {=$B7*C$2} -> 8045205.1 | D7: {=$B7*D$2} -> 16090410 | E7: {=$B7*E$2} -> 32180820 | F7: {=$B7*F$2} -> 48271231 | G7: {=$B7*G$2} -> 64361641
A9: {='presupuesto - Gastos'!E$35} -> 470920.29 | B9: {=$A9*B$2} -> 470920.29 | C9: {=$A9*C$2} -> 1412760.9 | D9: {=$A9*D$2} -> 2825521.7 | E9: {=$A9*E$2} -> 5651043.5 | F9: {=$A9*F$2} -> 8476565.2 | G9: {=$A9*G$2} -> 11302087
A10: {=AVERAGE('net worth - resumen | depósitos'!R44:R46)} -> 525158.67 | B10: {=$A10*B$2} -> 525158.67 | C10: {=$A10*C$2} -> 1575476 | D10: {=$A10*D$2} -> 3150952 | E10: {=$A10*E$2} -> 6301904 | F10: {=$A10*F$2} -> 9452856 | G10: {=$A10*G$2} -> 12603808
A11: {=AVERAGE('net worth - resumen | depósitos'!R56:R67)} -> -833717.83 | B11: {=$A11*B$2} -> -833717.83 | C11: {=$A11*C$2} -> -2501153.5 | D11: {=$A11*D$2} -> -5002307 | E11: {=$A11*E$2} -> -10004614 | F11: {=$A11*F$2} -> -15006921 | G11: {=$A11*G$2} -> -20009228
A13: 300000 | B13: {=$A13*B$2} -> 300000 | C13: {=$A13*C$2} -> 900000 | D13: {=$A13*D$2} -> 1800000 | E13: {=$A13*E$2} -> 3600000 | F13: {=$A13*F$2} -> 5400000 | G13: {=$A13*G$2} -> 7200000
A14: 400000 | B14: {=$A14*B$2} -> 400000 | C14: {=$A14*C$2} -> 1200000 | D14: {=$A14*D$2} -> 2400000 | E14: {=$A14*E$2} -> 4800000 | F14: {=$A14*F$2} -> 7200000 | G14: {=$A14*G$2} -> 9600000
A15: 500000 | B15: {=$A15*B$2} -> 500000 | C15: {=$A15*C$2} -> 1500000 | D15: {=$A15*D$2} -> 3000000 | E15: {=$A15*E$2} -> 6000000 | F15: {=$A15*F$2} -> 9000000 | G15: {=$A15*G$2} -> 12000000
A16: 600000 | B16: {=$A16*B$2} -> 600000 | C16: {=$A16*C$2} -> 1800000 | D16: {=$A16*D$2} -> 3600000 | E16: {=$A16*E$2} -> 7200000 | F16: {=$A16*F$2} -> 10800000 | G16: {=$A16*G$2} -> 14400000
A17: 700000 | B17: {=$A17*B$2} -> 700000 | C17: {=$A17*C$2} -> 2100000 | D17: {=$A17*D$2} -> 4200000 | E17: {=$A17*E$2} -> 8400000 | F17: {=$A17*F$2} -> 12600000 | G17: {=$A17*G$2} -> 16800000
A18: 800000 | B18: {=$A18*B$2} -> 800000 | C18: {=$A18*C$2} -> 2400000 | D18: {=$A18*D$2} -> 4800000 | E18: {=$A18*E$2} -> 9600000 | F18: {=$A18*F$2} -> 14400000 | G18: {=$A18*G$2} -> 19200000
A19: 900000 | B19: {=$A19*B$2} -> 900000 | C19: {=$A19*C$2} -> 2700000 | D19: {=$A19*D$2} -> 5400000 | E19: {=$A19*E$2} -> 10800000 | F19: {=$A19*F$2} -> 16200000 | G19: {=$A19*G$2} -> 21600000

Sheet presupuesto - APV - simulación 
A1: APV - simulación régimen B
A2: Tramos | C2: Tasa | E2: Cantidad afecta | F2: con APV | H2: impuesto | I2: con apv | K2: ∆
A3: 0.01 | B3: {=13.5*'variables - Table 1'!$B$3} -> 974538 | C3: 0 | E3: {=IF('presupuesto - Ingreso líquido'!$B$24>$A3,IF('presupuesto - Ingreso líquido'!$B$24>$B3,$B3-$A3,'presupuesto - Ingreso líquido'!$B$24-$A3),0)} -> 974537.99 | F3: {=IF('presupuesto - Ingreso líquido'!$B$24-B$11>$A3,IF('presupuesto - Ingreso líquido'!$B$24-B$11>$B3,$B3-$A3,'presupuesto - Ingreso líquido'!$B$24-B$11-$A3),0)} -> 974537.99 | H3: {=E3*$C3} -> 0 | I3: {=F3*$C3} -> 0 | K3: {=H3-I3} -> 0
A4: {=13.5*'variables - Table 1'!$B$3+0.01} -> 974538.01 | B4: {=30*'variables - Table 1'!$B$3} -> 2165640 | C4: 0.04 | E4: {=IF('presupuesto - Ingreso líquido'!$B$24>$A4,IF('presupuesto - Ingreso líquido'!$B$24>$B4,$B4-$A4,'presupuesto - Ingreso líquido'!$B$24-$A4),0)} -> 1191102 | F4: {=IF('presupuesto - Ingreso líquido'!$B$24-B$11>$A4,IF('presupuesto - Ingreso líquido'!$B$24-B$11>$B4,$B4-$A4,'presupuesto - Ingreso líquido'!$B$24-B$11-$A4),0)} -> 1191102 | H4: {=E4*$C4} -> 47644.08 | I4: {=F4*$C4} -> 47644.08 | K4: {=H4-I4} -> 0
A5: {=30*'variables - Table 1'!$B$3+0.01} -> 2165640 | B5: {=50*'variables - Table 1'!$B$3} -> 3609400 | C5: 0.08 | E5: {=IF('presupuesto - Ingreso líquido'!$B$24>$A5,IF('presupuesto - Ingreso líquido'!$B$24>$B5,$B5-$A5,'presupuesto - Ingreso líquido'!$B$24-$A5),0)} -> 1078561 | F5: {=IF('presupuesto - Ingreso líquido'!$B$24-B$11>$A5,IF('presupuesto - Ingreso líquido'!$B$24-B$11>$B5,$B5-$A5,'presupuesto - Ingreso líquido'!$B$24-B$11-$A5),0)} -> 685900.99 | H5: {=E5*C5} -> 86284.879 | I5: {=F5*C5} -> 54872.079 | K5: {=H5-I5} -> 31412.8
A6: {=50*'variables - Table 1'!$B$3} -> 3609400 | B6: {=70*'variables - Table 1'!$B$3} -> 5053160 | C6: 0.135 | E6: {=IF('presupuesto - Ingreso líquido'!$B$24>$A6,IF('presupuesto - Ingreso líquido'!$B$24>$B6,$B6-$A6,'presupuesto - Ingreso líquido'!$B$24-$A6),0)} -> 0 | F6: {=IF('presupuesto - Ingreso líquido'!$B$24-B$11>$A6,IF('presupuesto - Ingreso líquido'!$B$24-B$11>$B6,$B6-$A6,'presupuesto - Ingreso líquido'!$B$24-B$11-$A6),0)} -> 0 | H6: {=E6*C6} -> 0 | I6: {=F6*C6} -> 0 | K6: {=H6-I6} -> 0
A7: 4710580 | B7: 6056460 | C7: 0.23
A11: APV-b mensual | B11: 392660 | C11: {=B$11*12} -> 4711920 | H11: {=SUM(H3:H10)} -> 133928.96 | I11: {=SUM(I3:I10)} -> 102516.16 | K11: {=SUM(K3:K10)} -> 31412.8
I12: Anual | K12: {=K$11*12} -> 376953.6
A14: 15% máx APV-a | B14: {='net worth - Aporte APV'!B10} -> 240627 | C14: {='net worth - Aporte APV'!B10*15%} -> 36094.05

Sheet presupuesto - apv - rebaja impu
A1: apv - rebaja impuestos interés hipotecario
A2: tramos | C2: tasa | E2: cantidad afecta | F2: menos interés | H2: impuesto | I2: menos interés | K2: ∆
A3: 0.01 | B3: 8038926 | C3: 0 | E3: {=IF('presupuesto - Ingreso líquido'!$B$37>$A3,IF('presupuesto - Ingreso líquido'!$B$37>$B3,$B3-$A3,'presupuesto - Ingreso líquido'!$B$37-$A3),0)} -> 8038926 | F3: {=IF('presupuesto - Ingreso líquido'!$B$37-C$11>$A3,IF('presupuesto - Ingreso líquido'!$B$37-C$11>$B3,$B3-$A3,'presupuesto - Ingreso líquido'!$B$37-C$11-$A3),0)} -> 8038926 | H3: {=E3*$C3} -> 0 | I3: {=F3*$C3} -> 0 | K3: {=H3-I3} -> 0
A4: 8038926 | B4: 17864280 | C4: 0.04 | E4: {=IF('presupuesto - Ingreso líquido'!$B$37>$A4,IF('presupuesto - Ingreso líquido'!$B$37>$B4,$B4-$A4,'presupuesto - Ingreso líquido'!$B$37-$A4),0)} -> 9825354 | F4: {=IF('presupuesto - Ingreso líquido'!$B$37-C$11>$A4,IF('presupuesto - Ingreso líquido'!$B$37-C$11>$B4,$B4-$A4,'presupuesto - Ingreso líquido'!$B$37-C$11-$A4),0)} -> 9825354 | H4: {=E4*$C4} -> 393014.16 | I4: {=F4*$C4} -> 393014.16 | K4: {=H4-I4} -> 0
A5: {=17864280.01} -> 17864280 | B5: 29773800 | C5: 0.08 | E5: {=IF('presupuesto - Ingreso líquido'!$B$37>$A5,IF('presupuesto - Ingreso líquido'!$B$37>$B5,$B5-$A5,'presupuesto - Ingreso líquido'!$B$37-$A5),0)} -> 11909520 | F5: {=IF('presupuesto - Ingreso líquido'!$B$37-C$11>$A5,IF('presupuesto - Ingreso líquido'!$B$37-C$11>$B5,$B5-$A5,'presupuesto - Ingreso líquido'!$B$37-C$11-$A5),0)} -> 11909520 | H5: {=E5*C5} -> 952761.6 | I5: {=F5*C5} -> 952761.6 | K5: {=H5-I5} -> 0
A6: 29773800 | B6: 41683320 | C6: 0.135 | E6: {=IF('presupuesto - Ingreso líquido'!$B$37>$A6,IF('presupuesto - Ingreso líquido'!$B$37>$B6,$B6-$A6,'presupuesto - Ingreso líquido'!$B$37-$A6),0)} -> 9156612 | F6: {=IF('presupuesto - Ingreso líquido'!$B$37-C$11>$A6,IF('presupuesto - Ingreso líquido'!$B$37-C$11>$B6,$B6-$A6,'presupuesto - Ingreso líquido'!$B$37-C$11-$A6),0)} -> 4444779 | H6: {=E6*C6} -> 1236142.6 | I6: {=F6*C6} -> 600045.16 | K6: {=H6-I6} -> 636097.45
A7: 41683320 | B7: 53592840 | C7: 0.23 | E7: {=IF('presupuesto - Ingreso líquido'!$B$37>$A7,IF('presupuesto - Ingreso líquido'!$B$37>$B7,$B7-$A7,'presupuesto - Ingreso líquido'!$B$37-$A7),0)} -> 0 | F7: {=IF('presupuesto - Ingreso líquido'!$B$37-C$11>$A7,IF('presupuesto - Ingreso líquido'!$B$37-C$11>$B7,$B7-$A7,'presupuesto - Ingreso líquido'!$B$37-C$11-$A7),0)} -> 0
A11: APV-b mensual | B11: {=ROUND(C$11/12,0)} -> 392653 | C11: {=SUM('depto - dividendos'!BG17:BG27,'depto - dividendos'!BG15)} -> 4711833 | H11: {=SUM(H3:H10)} -> 2581918.4 | I11: {=SUM(I3:I10)} -> 1945820.9 | K11: {=SUM(K3:K10)} -> 636097.45
A12: o intereses
A14: 15% máx APV-a | B14: {='net worth - Aporte APV'!B10} -> 240627 | C14: {='net worth - Aporte APV'!B10*15%} -> 36094.05

Sheet flujos - Gasto mes actual
A1: Gasto mes actual
A2: Agosto | B2: Total diario | C2: Supermercado | G2: Carrete | K2: Comida | O2: Ropa | S2: Otros | W2: Drugs | Z2: Cuentas | AD2: Salud | AH2: Transporte | AL2: Dólares | AN2: Repasar esta columna
A3: 44409 | B3: {=SUM(C3:AI3)} -> 800000 | E3: FALSE | I3: FALSE | M3: FALSE | Q3: FALSE | U3: FALSE | Z3: hipotecario | AA3: {='depto - dividendos'!J22} -> 800000 | AB3: FALSE | AF3: FALSE | AH3: mobike | AI3: {=ROUND(AM3*'variables - Table 1'!$B$5,0)} -> 0 | AJ3: FALSE | AL3: mobike | AM3: 0 | AN3: {=ROUND(AM3*'variables - Table 1'!$B$5,0)} -> 0 | AO3: FALSE
A4: 44410 | B4: {=SUM(C4:AI4)} -> 80000 | E4: FALSE | I4: FALSE | M4: FALSE | Q4: FALSE | U4: FALSE | Z4: gastos comunes | AA4: 80000 | AB4: FALSE | AF4: FALSE | AH4: cabify | AI4: {=AN4} -> 0 | AJ4: FALSE | AL4: cabify | AN4: {=ROUND(AM4*'variables - Table 1'!$B$5,0)} -> 0 | AO4: FALSE
A5: 44411 | B5: {=SUM(C5:AI5)} -> 21000 | E5: FALSE | I5: FALSE | M5: FALSE | Q5: FALSE | U5: FALSE | Z5: entel | AA5: 21000 | AB5: FALSE | AF5: FALSE | AH5: costanera norte | AJ5: FALSE | AN5: {=ROUND(AM5*'variables - Table 1'!$B$5,0)} -> 0 | AO5: FALSE
A6: 44412 | B6: {=SUM(C6:AI6)} -> 7465 | E6: FALSE | I6: FALSE | M6: FALSE | Q6: FALSE | U6: FALSE | Z6: electricidad | AA6: {='flujos - Table 3-1-1'!D17} -> 7465 | AB6: FALSE | AF6: FALSE | AH6: vespucio sur | AJ6: FALSE | AL6: delivery | AM6: {=0} -> 0 | AN6: {=ROUND(AM6*'variables - Table 1'!$B$5,0)} -> 0 | AO6: FALSE
A7: 44413 | B7: {=SUM(C7:AI7)} -> 22352 | E7: FALSE | I7: FALSE | M7: FALSE | Q7: FALSE | U7: FALSE | Z7: gas | AA7: {='flujos - Table 3-1-1'!D62} -> 22352 | AB7: FALSE | AF7: FALSE | AH7: bencina | AJ7: FALSE | AL7: suscripciones | AM7: {=(4.34+2.43)*0} -> 0 | AN7: {=ROUND(AM7*'variables - Table 1'!$B$5,0)} -> 0 | AO7: FALSE
A8: 44414 | B8: {=SUM(C8:AI8)} -> 0 | E8: FALSE | I8: FALSE | M8: FALSE | Q8: FALSE | U8: FALSE | Z8: suscripciones | AA8: {=AN7} -> 0 | AB8: FALSE | AF8: FALSE | AH8: bip | AJ8: FALSE | AL8: amazon | AN8: {=ROUND(AM8*'variables - Table 1'!$B$5,0)} -> 0 | AO8: FALSE
A9: 44415 | B9: {=SUM(C9:AI9)} -> 0 | E9: FALSE | I9: FALSE | M9: FALSE | Q9: FALSE | U9: FALSE | AB9: FALSE | AF9: FALSE | AH9: estacionamiento | AJ9: FALSE | AN9: {=ROUND(AM9*'variables - Table 1'!$B$5,0)} -> 0 | AO9: FALSE
A10: 44416 | B10: {=SUM(C10:AI10)} -> 0 | E10: FALSE | I10: FALSE | M10: FALSE | Q10: FALSE | U10: FALSE | AB10: FALSE | AF10: FALSE | AJ10: FALSE | AN10: {=ROUND(AM10*'variables - Table 1'!$B$5,0)} -> 0 | AO10: FALSE
A11: 44417 | B11: {=SUM(C11:AI11)} -> 0 | E11: FALSE | I11: FALSE | M11: FALSE | Q11: FALSE | U11: FALSE | AB11: FALSE | AF11: FALSE | AJ11: FALSE | AN11: {=ROUND(AM11*'variables - Table 1'!$B$5,0)} -> 0 | AO11: FALSE
A12: 44418 | B12: {=SUM(C12:AI12)} -> 0 | E12: FALSE | I12: FALSE | M12: FALSE | Q12: FALSE | U12: FALSE | AB12: FALSE | AF12: FALSE | AJ12: FALSE | AO12: FALSE
A13: 44419 | B13: {=SUM(C13:AI13)} -> 0 | E13: FALSE | I13: FALSE | M13: FALSE | Q13: FALSE | U13: FALSE | AB13: FALSE | AF13: FALSE | AJ13: FALSE | AN13: {=ROUND(AM13*'variables - Table 1'!$B$5,0)} -> 0 | AO13: FALSE
A14: 44420 | B14: {=SUM(C14:AI14)} -> 0 | E14: FALSE | I14: FALSE | M14: FALSE | Q14: FALSE | U14: FALSE | AB14: FALSE | AF14: FALSE | AJ14: FALSE | AN14: {=ROUND(AM14*'variables - Table 1'!$B$5,0)} -> 0 | AO14: FALSE
A15: 44421 | B15: {=SUM(C15:AI15)} -> 0 | E15: FALSE | I15: FALSE | M15: FALSE | Q15: FALSE | U15: FALSE | AB15: FALSE | AF15: FALSE | AJ15: FALSE | AN15: {=ROUND(AM15*'variables - Table 1'!$B$5,0)} -> 0 | AO15: FALSE
A16: 44422 | B16: {=SUM(C16:AI16)} -> 0 | E16: FALSE | I16: FALSE | M16: FALSE | Q16: FALSE | U16: FALSE | AB16: FALSE | AF16: FALSE | AJ16: FALSE | AN16: {=ROUND(AM16*'variables - Table 1'!$B$5,0)} -> 0 | AO16: FALSE
A17: 44423 | B17: {=SUM(C17:AI17)} -> 0 | E17: FALSE | I17: FALSE | M17: FALSE | Q17: FALSE | U17: FALSE | AB17: FALSE | AF17: FALSE | AJ17: FALSE | AN17: {=ROUND(AM17*'variables - Table 1'!$B$5,0)} -> 0 | AO17: FALSE
A18: 44424 | B18: {=SUM(C18:AI18)} -> 0 | E18: FALSE | I18: FALSE | M18: FALSE | Q18: FALSE | U18: FALSE | AB18: FALSE | AF18: FALSE | AJ18: FALSE | AN18: {=ROUND(AM18*'variables - Table 1'!$B$5,0)} -> 0 | AO18: FALSE
A19: 44425 | B19: {=SUM(C19:AI19)} -> 0 | E19: FALSE | I19: FALSE | M19: FALSE | Q19: FALSE | U19: FALSE | AB19: FALSE | AF19: FALSE | AJ19: FALSE | AN19: {=ROUND(AM19*'variables - Table 1'!$B$5,0)} -> 0 | AO19: FALSE
A20: 44426 | B20: {=SUM(C20:AI20)} -> 0 | E20: FALSE | I20: FALSE | M20: FALSE | Q20: FALSE | U20: FALSE | AB20: FALSE | AF20: FALSE | AJ20: FALSE | AN20: {=ROUND(AM20*'variables - Table 1'!$B$5,0)} -> 0 | AO20: FALSE
A21: 44427 | B21: {=SUM(C21:AI21)} -> 0 | E21: FALSE | I21: FALSE | M21: FALSE | Q21: FALSE | U21: FALSE | AB21: FALSE | AF21: FALSE | AJ21: FALSE | AN21: {=ROUND(AM21*'variables - Table 1'!$B$5,0)} -> 0 | AO21: FALSE
A22: 44428 | B22: {=SUM(C22:AI22)} -> 0 | E22: FALSE | I22: FALSE | M22: FALSE | Q22: FALSE | U22: FALSE | AB22: FALSE | AF22: FALSE | AJ22: FALSE | AN22: {=ROUND(AM22*'variables - Table 1'!$B$5,0)} -> 0 | AO22: FALSE
A23: 44429 | B23: {=SUM(C23:AI23)} -> 0 | E23: FALSE | I23: FALSE | M23: FALSE | Q23: FALSE | U23: FALSE | AB23: FALSE | AF23: FALSE | AJ23: FALSE | AN23: {=ROUND(AM23*'variables - Table 1'!$B$5,0)} -> 0 | AO23: FALSE
A24: 44430 | B24: {=SUM(C24:AI24)} -> 0 | E24: FALSE | I24: FALSE | M24: FALSE | Q24: FALSE | U24: FALSE | AB24: FALSE | AF24: FALSE | AJ24: FALSE | AN24: {=ROUND(AM24*'variables - Table 1'!$B$5,0)} -> 0 | AO24: FALSE
... A34: 44440 | B34: {=SUM(C34:AI34)} -> 0 | E34: FALSE | I34: FALSE | M34: FALSE | Q34: FALSE | U34: FALSE | AB34: FALSE | AF34: FALSE | AJ34: FALSE | AN34: {=ROUND(AM34*'variables - Table 1'!$B$5,0)} -> 0 | AO34: FALSE
E35: FALSE | I35: FALSE | M35: FALSE | Q35: FALSE | U35: FALSE | AB35: FALSE | AD35: Isapre | AE35: {='presupuesto - Ingreso líquido'!$D$19*0} -> 0 | AJ35: FALSE | AM35: Diferencia | AN35: {=SUM(AN3:AN34,-AN$37)} -> 0 | AO35: FALSE
E36: FALSE | I36: FALSE | M36: FALSE | Q36: FALSE | U36: FALSE | AB36: FALSE | AJ36: FALSE | AO36: FALSE
B37: {=SUM(B3:B34)+AE35} -> 930817 | C37: Supermercado | D37: {=SUM(D3:D36)} -> 0 | G37: Carrete | H37: {=SUM(H3:H36)} -> 0 | K37: Almuerzo | L37: {=SUM(L3:L36)} -> 0 | O37: Ropa | P37: {=SUM(P3:P36)} -> 0 | S37: Otros | T37: {=SUM(T3:T36)} -> 0 | W37: Mota | X37: {=SUM(X3:X36)} -> 0 | Z37: Cuentas | AA37: {=SUM(AA3:AA36)} -> 930817 | AD37: Salud | AE37: {=SUM(AE3:AE36)} -> 0 | AH37: Transporte | AI37: {=SUM(AI3:AI36)} -> 0 | AL37: Dólares | AM37: {=SUM(AM3:AM34)} -> 0 | AN37: {=ROUND(AM37*'variables - Table 1'!$B$5,0)} -> 0

Sheet flujos - Table 1-3
D1: febrero | E1: {=SUM(D2:D118)} -> 8638334
A4: 12/12/2024 | C4: 8 BITS | D4: 49990
A5: 07/02/2025 | C5: AGUA LUNA | D5: 23900
A6: 06/02/2025 | C6: AHUM L272 LOS LEONES 1160 | D6: 31534
C7: AHUM L526 ALC.INFANT 1541 | D7: 24094
C8: ALANA | D8: 1500
C9: ALMACENES BILBAO | D9: 4530
A10: 05/02/2025 | C10: ALMACENES BILBAO | D10: 2010
A11: 04/02/2025 | C11: ALMACENES BILBAO | D11: 2020
C12: ALMACENES BILBAO | D12: 5200
A13: 21/02/2025 | C13: APOTECARIO VAPE SHOP | D13: 30000
A14: 05/12/2024 | C14: APPLE.COM CL APPLE | D14: 22664
A15: 03/12/2024 | C15: APPLE.COM CL APPLE | D15: 9166
C16: APPLE.COM CL APPLE | D16: 9166
C17: APPLE.COM CL APPLE | D17: 9166
A18: 12/02/2025 | C18: B-1326 PENALOLEN | D18: 19400
A19: 23/01/2025 | C19: BEE MARKET | D19: 3450
C20: BOTILLERIA LA MALTIT | D20: 3300
A21: 22/02/2025 | C21: BOTILLERIA PORTEZUELO | D21: 4400
A22: 10/02/2025 | C22: CARNES LOS PLOMOS | D22: 8796
A23: 15/02/2025 | C23: COPEC APP | D23: 30000
C24: CORP. CULTURAL DE LA ESTA | D24: 5000
C25: DANIELA ANDREA GARCIA YAN | D25: 13800
C26: ENEL | D26: 64832
C27: ENTEL HOGAR | D27: 21990
C28: EXPRESS PLAZA LYON | D28: 33203
C29: FU XING | D29: 3000
C30: GOOGLE PLAY YOUTUBE | D30: 9200
A31: 4/02/2025 | C31: INTERESES | D31: 735
C32: JACK&JONES OPEN PLAZA | D32: 9240
A33: 28/01/2025 | C33: JUMBO COSTANERA CENTER | D33: 26876
A34: 24/01/2025 | C34: JUMBO COSTANERA CENTER | D34: 9394
C35: LA CABRERA ISIDORA | D35: 159950
A36: 20/01/2025 | C36: LATAM.COM XP INTER | D36: 618677
C37: LONDON COFFEE ALCANTARA | D37: 5460
C38: LONDON COFFEE ALCANTARA | D38: 5460
C39: LONDON COFFEE ALCANTARA | D39: 5460
C40: LONDON COFFEE ALCANTARA | D40: 5460
A41: 17/02/2025 | C41: LONDON COFFEE ALCANTARA | D41: 4680
A42: 30/01/2025 | C42: LONDON COFFEE ALCANTARA | D42: 5460
...

Sheet flujos - Table 1-2
D1: enero | E1: {=SUM(D2:D118)} -> 3021683
A4: 12/12/2024 | C4: 8 BITS | D4: 49990
C5: AGUA LUNA | D5: 23900
C6: AHUM L272 LOS LEONES 1160 | D6: 42710
C7: ALMACENES BILBAO | D7: 2720
C8: ALMACENES BILBAO | D8: 3130
A9: 18/01/2025 | C9: ALMACENES BILBAO | D9: 1650
C10: ALMACENES BILBAO | D10: 3510
A11: 17/01/2025 | C11: ALMACENES BILBAO | D11: 2230
C12: ALMACENES BILBAO | D12: 3380
A13: 11/01/2025 | C13: ALMACENES BILBAO | D13: 4050
A14: 10/01/2025 | C14: ALMACENES BILBAO | D14: 3500
C15: ALMACENES BILBAO | D15: 2930
A16: 08/01/2025 | C16: ALMACENES BILBAO | D16: 2400
A17: 07/01/2025 | C17: ALMACENES BILBAO | D17: 1860
A18: 06/01/2025 | C18: ALMACENES BILBAO | D18: 1330
A19: 03/01/2025 | C19: ALMACENES BILBAO | D19: 3120
C20: ALMACENES BILBAO | D20: 1250
C21: ALMACENES BILBAO | D21: 1800
A22: 24/12/2024 | C22: ALMACENES BILBAO | D22: 7250
A23: 23/12/2024 | C23: ALMACENES BILBAO | D23: 3260
C24: ALTO LAS CONDES | D24: 14500
C25: ANTARTICA COSTANERA H2H | D25: 11090
A26: 05/12/2024 | C26: APPLE.COM CL APPLE | D26: 22663
A27: 03/12/2024 | C27: APPLE.COM CL APPLE | D27: 9166
C28: APPLE.COM CL APPLE | D28: 9166
C29: APPLE.COM CL APPLE | D29: 9166
C30: C. VERDE PROVIDENC 2594 | D30: 3890
C31: CARNES LOS PLOMOS | D31: 10667
A32: 25/12/2024 | C32: COMERCIAL MAHO LIMITADA | D32: 20000
C33: COPEC APP | D33: 53580
C34: COPEC PROVIDENCIA | D34: 4400
C35: ENCANTI | D35: 10651
C36: ENEL | D36: 42263
A37: 20/12/2024 | C37: ENEL | D37: 32998
C38: ENTEL HOGAR | D38: 12990
A39: 14/01/2025 | C39: EXPRESS PLAZA LYON | D39: 16131
C40: EXPRESS PLAZA LYON | D40: 29270
A41: 28/12/2024 | C41: EXPRESS PLAZA LYON | D41: 39660
A42: 16/01/2025 | C42: FALABELLA ALTO LAS CONDES | D42: 4000
...

Sheet flujos - Table 1-4
D1: marzo | E1: {=SUM(D2:D118)} -> 5445661
C3: AHUM L272 LOS LEONES 1160 | D3: 15799
C4: AHUM L272 LOS LEONES 1160 | D4: 8499
C5: APOTECARIO VAPE SHOP | D5: 23000
A6: 03/12/2024 | C6: APPLE.COM CL APPLE | D6: 9166
C7: APPLE.COM CL APPLE | D7: 9166
C8: APPLE.COM CL APPLE | D8: 9166
A9: 10/03/2025 | C9: AUTOSERVICIO CL ALEMANA | D9: 10281
C10: BELLAS ARTES EXPRESS | D10: 1300
C11: BELLAS ARTES EXPRESS | D11: 2870
A12: 09/03/2025 | C12: CALVIN KLEIN PARQUE | D12: 49980
C13: CHICKEN FACTORY | D13: 19980
A14: 21/03/2025 | C14: COPEC APP | D14: 20000
C15: COPEC APP | D15: 49077
C16: COPEC APP | D16: 4580
A17: 27/02/2025 | C17: COPEC APP | D17: 52154
C18: DL*BOOKINGCOM | D18: 98304
C19: ENEL | D19: 60849
A20: 13/03/2025 | C20: ENTEL HOGAR | D20: 21990
A21: 15/03/2025 | C21: EXPRESS AVDA VALPARAI | D21: 32110
C22: EXPRESS AVDA VALPARAI | D22: 10820
A23: 26/02/2025 | C23: FLOW *PINARES.CL | D23: 200000
C24: GOOGLE PLAY YOUTUBE CL | D24: 9200
C25: HAULMER*LA BOTISHOP | D25: 800
A26: 25/03/2025 | C26: INTERESES | D26: 105
C27: JUMBO ALTO LAS CONDES | D27: 42627
C28: JUMBO ALTO LAS CONDES | D28: 36561
C29: JUMBO ALTO LAS CONDES | D29: 20900
C30: JUMBO ALTO LAS CONDES | D30: 35552
C31: JUMBO COSTANERA CENTER | D31: 32142
C32: JUMBO COSTANERA CENTER | D32: 46162
C33: LA CABRERA ISIDORA | D33: 143940
A34: 20/01/2025 | C34: LATAM.COM XP INTER | D34: 618676
A35: 24/03/2025 | C35: LONDON COFFEE ALCANTARA | D35: 4680
C36: LONDON COFFEE ALCANTARA | D36: 5460
A37: 20/03/2025 | C37: LONDON COFFEE ALCANTARA | D37: 8603
A38: 19/03/2025 | C38: LONDON COFFEE ALCANTARA | D38: 5460
C39: LONDON COFFEE ALCANTARA | D39: 5460
C40: LONDON COFFEE ALCANTARA | D40: 4680
C41: LONDON COFFEE ALCANTARA | D41: 5460
...

Sheet flujos - Table 3-1-1
D1: mayo | E1: {=SUM(D2:D118)} -> 4395731
C3: ALMACENES BILBAO | D3: 2200
C4: ALMACENES BILBAO | D4: 2700
A5: 03/12/2024 | C5: APPLE.COM CL APPLE | D5: 9166
C6: APPLE.COM CL APPLE | D6: 9166
C7: APPLE.COM CL APPLE | D7: 9166
C8: AUTOSERVICIO CL ALEMANA | D8: 5512
C9: CK ECOMMERCE | D9: 79980
A10: 29/04/2025 | C10: CK ECOMMERCE | D10: 39990
A11: 10/05/2025 | C11: COPEC APP | D11: 53571
C12: DANIELA ANDREA GARCIA YAN | D12: 13800
A13: 28/04/2025 | C13: EASY COSTANERA CENTER | D13: 150
C14: EASY COSTANERA CENTER | D14: 1900
C15: EASY COSTANERA CENTER | D15: 18170
C16: EASY INTERNET | D16: 33481
A17: 22/04/2025 | C17: ENEL | D17: 7465
C18: ENTEL HOGAR | D18: 21990
C19: EXPRESS PLAZA LYON | D19: 4980
A20: 07/05/2025 | C20: EXPRESS PLAZA LYON | D20: 17100
C21: EXPRESS PLAZA LYON | D21: 24460
C22: FABRICA | D22: 8000
C23: FLOW *PINARES.CL | D23: 200000
A24: 15/05/2025 | C24: GOOGLE PLAY YOUTUBE CL | D24: 11000
C25: IKEA OPEN KENNEDY | D25: 9970
A26: 22/05/2025 | C26: INTERESES | D26: 1896
C27: INVERSIONES MONASTRELL WI | D27: 97650
A28: 21/05/2025 | C28: JUMBO COSTANERA CENTER | D28: 27401
A29: 17/05/2025 | C29: JUMBO COSTANERA CENTER | D29: 9724
C30: JUMBO COSTANERA CENTER | D30: 21695
C31: JUMBO COSTANERA CENTER | D31: 46128
C32: JUMBO COSTANERA CENTER | D32: 65514
A33: 04/05/2025 | C33: JUMBO COSTANERA CENTER | D33: 52400
C34: JUMBO COSTANERA CENTER | D34: 44885
A35: 26/04/2025 | C35: JUMBO COSTANERA CENTER | D35: 44055
C36: JUMBO COSTANERA CENTER | D36: 34246
C37: LONDON COFFEE ALCANTARA | D37: 5460
C38: LONDON COFFEE ALCANTARA | D38: 5460
C39: LONDON COFFEE ALCANTARA | D39: 5460
C40: LONDON COFFEE ALCANTARA | D40: 6300
C41: LONDON COFFEE ALCANTARA | D41: 5460
...

Sheet flujos - Table 3-1-1-1
D1: {=SUM(D2:D118)} -> 4490361
A2: 13/06/2025 | C2: ALMACENES BILBAO | D2: 2680
C3: ALMACENES BILBAO | D3: 5240
A4: 26/05/2025 | C4: ALMACENES BILBAO | D4: 1360
A5: 03/12/2024 | C5: APPLE.COM CL APPLE | D5: 9166
C6: APPLE.COM CL APPLE | D6: 9166
C7: APPLE.COM CL APPLE | D7: 9166
A8: 03/06/2025 | C8: BOOKING.COM | D8: 210132
C9: DOCKERS COSTANERA CENTER | D9: 44990
A10: 23/05/2025 | C10: ENEL | D10: 42655
C11: ENTEL HOGAR | D11: 21990
C12: EXPRESS PLAZA LYON | D12: 8758
A13: 10/06/2025 | C13: FLOW *PINARES.CL | D13: 200000
A14: 27/05/2025 | C14: FLOW *PINARES.CL | D14: 200000
C15: GOOGLE PLAY YOUTUBE CL | D15: 11000
C16: IBERIA OPERADORA SA TCOMP | D16: 30000
C17: IMPTO. DECRETO LEY 3475 | D17: 1063
A18: 23/06/2025 | C18: INTERESES | D18: 1818
C19: INVERSIONES EL PARRON SA | D19: 4800
C20: JUMBO ALTO LAS CONDES | D20: 16175
C21: JUMBO COSTANERA CENTER | D21: 26864
A22: 18/06/2025 | C22: JUMBO COSTANERA CENTER | D22: 54633
A23: 14/06/2025 | C23: JUMBO COSTANERA CENTER | D23: 29254
C24: JUMBO COSTANERA CENTER | D24: 36392
A25: 08/06/2025 | C25: JUMBO COSTANERA CENTER | D25: 26432
A26: 06/06/2025 | C26: JUMBO COSTANERA CENTER | D26: 30459
A27: 04/06/2025 | C27: JUMBO COSTANERA CENTER | D27: 53404
A28: 01/06/2025 | C28: JUMBO COSTANERA CENTER | D28: 41047
C29: JUMBO COSTANERA CENTER | D29: 33943
C30: JUMBO COSTANERA CENTER | D30: 38468
A31: 25/05/2025 | C31: JUMBO COSTANERA CENTER | D31: 34880
A32: 24/05/2025 | C32: JUMBO COSTANERA CENTER | D32: 16105
C33: LA CABRERA ALONSO | D33: 158060
C34: LA CABRERA ALONSO | D34: 139080
C35: LATAM.COM XP INTER | D35: 336070
C36: LONDON COFFEE ALCANTARA | D36: 5460
C37: LONDON COFFEE ALCANTARA | D37: 9660
C38: LONDON COFFEE ALCANTARA | D38: 10920
C39: LONDON COFFEE ALCANTARA | D39: 5460
C40: LONDON COFFEE ALCANTARA | D40: 4680
...

Sheet flujos - Table 3-1
D1: abril | E1: {=SUM(D2:D118)} -> 3759856
C4: ALMACENES BILBAO | D4: 7360
A5: 08/04/2025 | C5: ALMACENES BILBAO | D5: 4360
A6: 03/12/2024 | C6: APPLE.COM CL APPLE | D6: 9166
C7: APPLE.COM CL APPLE | D7: 9166
C8: APPLE.COM CL APPLE | D8: 9166
C9: COPEC APP | D9: 48873
C10: COSTANERA CENTER | D10: 23600
C11: DP *IKEA COM | D11: 14960
A12: 02/04/2025 | C12: DP *IKEA COM | D12: 113910
A13: 17/04/2025 | C13: EASY COSTANERA CENTER | D13: 2990
C14: EASY COSTANERA CENTER | D14: 27670
C15: EASY COSTANERA CENTER | D15: 7990
A16: 14/04/2025 | C16: ENTEL HOGAR | D16: 21990
A17: 18/04/2025 | C17: EXPRESS PLAZA LYON | D17: 8430
A18: 12/04/2025 | C18: EXPRESS PLAZA LYON | D18: 21020
A19: 06/04/2025 | C19: EXPRESS PLAZA LYON | D19: 13460
A20: 04/04/2025 | C20: EXPRESS PLAZA LYON | D20: 22130
C21: EXPRESS PLAZA LYON | D21: 20160
A22: 21/04/2025 | C22: FLOW *PINARES.CL | D22: 200000
C23: FLOW *PINARES.CL | D23: 200000
C24: GOOGLE PLAY YOUTUBE CL | D24: 9200
A25: 05/04/2025 | C25: IKEA OPEN KENNEDY | D25: 8980
C26: INVERSIONES MONASTRELL WI | D26: 85120
C27: JUMBO ALTO LAS CONDES | D27: 14170
C28: JUMBO ALTO LAS CONDES | D28: 34776
A29: 19/04/2025 | C29: JUMBO COSTANERA CENTER | D29: 16678
C30: JUMBO COSTANERA CENTER | D30: 32703
C31: JUMBO COSTANERA CENTER | D31: 12135
C32: JUMBO COSTANERA CENTER | D32: 17725
C33: JUMBO COSTANERA CENTER | D33: 16719
C34: LONDON COFFEE ALCANTARA | D34: 4680
C35: LONDON COFFEE ALCANTARA | D35: 5460
C36: LONDON COFFEE ALCANTARA | D36: 5460
C37: LONDON COFFEE ALCANTARA | D37: 1470
C38: LONDON COFFEE ALCANTARA | D38: 4680
C39: LONDON COFFEE ALCANTARA | D39: 7105
A40: 10/04/2025 | C40: LONDON COFFEE ALCANTARA | D40: 5460
C41: LONDON COFFEE ALCANTARA | D41: 5460
C42: LONDON COFFEE ALCANTARA | D42: 5460
...

Sheet flujos - Totales
A1: Totales
A2: Deuda pagada | B2: {=0} -> 0 | C2: {=0} -> 0 | D2: Internet
A3: Gasto falso | B3: {='flujos - Gasto mes actual'!T9} -> 0 | D3: {=B4*1} -> 50817
A4: Deuda nacional | B4: {='flujos - Gasto mes actual'!B$37-'flujos - Gasto mes actual'!AE35-'flujos - Gasto mes actual'!AN$37-B6-B2-B9-'flujos - Gasto mes actual'!AN35+'flujos - Table 2-1'!B$9} -> 50817 | D4: {=D3-B4} -> 0
A5: Internacional | B5: {=IF('flujos - Gasto mes actual'!AM$37-C2<0,0,ROUND(C5*'variables - Table 1'!$B$5,0))} -> 0 | C5: {='flujos - Gasto mes actual'!AM$37-C2} -> 0 | D5: {=C5*1} -> 0
A6: Efectivo | B6: {='flujos - Gasto mes actual'!AA3+'flujos - Gasto mes actual'!AA4+'flujos - Gasto mes actual'!X$37+C6} -> 880000 | C6: {=0} -> 0 | D6: {=D5-C5} -> 0
A7: Cuentas | B7: {='flujos - Gasto mes actual'!AA$37} -> 930817
A9: Líder Mastercard | B9: {=SUMIF('flujos - Gasto mes actual'!E3:E36,"=TRUE",'flujos - Gasto mes actual'!D3:D36)+SUMIF('flujos - Gasto mes actual'!U3:U36,"=TRUE",'flujos - Gasto mes actual'!T3:T36)+SUMIF('flujos - Gasto mes actual'!M3:M36,"=TRUE",'flujos - Gasto mes actual'!L3:L36)+SUMIF('flujos - Gasto mes actual'!AB3:AB36,"=TRUE",'flujos - Gasto mes actual'!AA3:AA36)+SUMIF('flujos - Gasto mes actual'!I3:I36,"=TRUE",'flujos - Gasto mes actual'!H3:H36)+SUMIF('flujos - Gasto mes actual'!Q3:Q36,"=TRUE",'flujos - Gasto mes actual'!P3:P36)+SUMIF('flujos - Gasto mes actual'!AF3:AF34,"=TRUE",'flujos - Gasto mes actual'!AE3:AE34)+SUMIF('flujos - Gasto mes actual'!AO3:AO36,"=TRUE",'flujos - Gasto mes actual'!AN3:AN36)+SUMIF('flujos - Gasto mes actual'!AJ3:AJ36,"=TRUE",'flujos - Gasto mes actual'!AI3:AI36)} -> 0
A12: Salud | B12: {='flujos - Gasto mes actual'!AE$37} -> 0
A13: Transporte | B13: {='flujos - Gasto mes actual'!AI$37} -> 0
A14: Not monthly | B14: {=0} -> 0
A16: Total gastos | B16: {='flujos - Gasto mes actual'!D$37+'flujos - Gasto mes actual'!H$37+'flujos - Gasto mes actual'!L$37+'flujos - Gasto mes actual'!P$37+'flujos - Gasto mes actual'!T$37+'flujos - Gasto mes actual'!X$37+'flujos - Gasto mes actual'!AA$37+'flujos - Gasto mes actual'!AE$37+'flujos - Gasto mes actual'!AI$37} -> 930817 | C16: Cupo disponible | D16: {=12720000-B4} -> 12669183
A17: - líder | B17: {=B$16-B9-B3} -> 930817 | D17: {=7735-'flujos - Gasto mes actual'!AM$37} -> 7735

Sheet flujos - Table 2-1
A1: Cuenta corriente | B1: {='net worth - cash'!B2} -> 280744
A2: Adelantado | B2: 0
A4: Efectivo | B4: 0
A5: Mach | B5: 0
A7: Líquido bruto | B7: {=B1+B2} -> 280744
A8: Deuda | B8: {=SUM('flujos - Totales'!B4:B5)} -> 50817
A9: Deuda mes anterior | B9: 0
A10: Líquido mes neto | B10: {=B$7-SUM(B$8)+B4+B5} -> 229927

Sheet flujos - Table 3-2
A1: apple music
A2: apple cloud storage
A3: apple tv
A4: youtube family

Sheet flujos - Gasto mensual
A1: Gasto mensual
B2: usd | C2: Ingreso | D2: Bruto | E2: Líquido | F2: Isapre | G2: AFP | H2: Adicional | I2: Saldo tc | J2: Crédito | K2: Ahorro | M2: Gasto real | N2: Gasto | P2: Supermercado | Q2: Carrete | R2: take out | S2: Ropa | T2: Otros | U2: Cuentas | V2: Drugs | W2: Salud | X2: Transporte | Y2: Cabify | Z2: Scooters | AA2: Delivery | AB2: Dólares | AC2: Crédito | AE2: Líder + falso | AF2: Líder Mastercard | AG2: Falso | AH2: Not monthly
A3: 42887 | B3: {=ROUND(C3/'variables - Table 1-1'!B2,0)} -> 1869 | C3: {=SUM(E3:J3)} -> 1242048 | D3: {=SUM(E3:G3)} -> 1122048 | E3: {=949283} -> 949283 | F3: 68402 | G3: {='net worth - retiro'!D5} -> 104363 | H3: {=120000} -> 120000 | J3: 0 | K3: {=529723} -> 529723 | L3: {=(K3/C3)} -> 0.42649157 | M3: {=N3-AF3} -> 493368 | N3: 529723 | P3: 125333.75 | Q3: 36781.25 | R3: 38820 | S3: 15516 | T3: 93575 | U3: 0 | V3: 106750 | W3: 115902 | X3: 129891 | AB3: 125717.91 | AC3: 0 | AE3: 36355 | AF3: 36355
A4: 42917 | B4: {=ROUND(C4/'variables - Table 1-1'!B3,0)} -> 2132 | C4: {=SUM(E4:J4)} -> 1392783 | D4: {=SUM(E4:G4)} -> 1192783 | E4: {=1009422} -> 1009422 | F4: 72765 | G4: {='net worth - retiro'!D6} -> 110596 | H4: {=150000+50000} -> 200000 | J4: 0 | K4: {=C4-N4} -> 594770 | L4: {=(K4/C4)} -> 0.42703709 | M4: {=N4-AF4} -> 658013 | N4: {=SUM(P4:AB4)} -> 798013 | P4: 172023 | Q4: 35325 | R4: 41390 | S4: 39980 | T4: 112520 | U4: 0 | V4: 120000 | W4: 122765 | X4: 125000 | AB4: {=ROUND(29009.587,0)} -> 29010 | AC4: {=J3} -> 0 | AE4: 140000 | AF4: 140000
A5: 42948 | B5: {=ROUND(C5/'variables - Table 1-1'!B4,0)} -> 2265 | C5: {=SUM(E5:J5)} -> 1430407 | D5: {=SUM(E5:G5)} -> 1310407 | E5: {=1105094} -> 1105094 | F5: 81804 | G5: {='net worth - retiro'!D7} -> 123509 | H5: {=120000} -> 120000 | J5: 0 | K5: {=C5-N5} -> 607902.89 | L5: {=(K5/C5)} -> 0.42498596 | M5: {=N5-AF5} -> 687504.11 | N5: {=SUM(P5:AB5)} -> 822504.11 | P5: 101864 | Q5: 40720 | R5: 39790 | S5: 0 | T5: 227430 | U5: 0 | V5: 90000 | W5: 131804 | X5: 159761 | AB5: 31135.112 | AC5: {=J4} -> 0 | AE5: 135000 | AF5: 135000
A6: 42979 | B6: {=ROUND(C6/'variables - Table 1-1'!B5,0)} -> 2323 | C6: {=SUM(E6:J6)} -> 1475760 | D6: {=SUM(E6:G6)} -> 1305760 | E6: {=1101255} -> 1101255 | F6: 81471 | G6: {='net worth - retiro'!D8} -> 123034 | H6: {=30000*4+50000} -> 170000 | J6: 0 | K6: {=C6-N6} -> 379127 | L6: {=(K6/C6)} -> 0.25690288 | M6: {=N6-AF6} -> 909333 | N6: {=SUM(P6:AB6)} -> 1096633 | P6: 93609 | Q6: 47440 | R6: 44690 | S6: 0 | T6: 107710 | U6: 0 | V6: 97000 | W6: 171471 | X6: 120817 | AB6: 413896 | AC6: {=J5} -> 0 | AE6: 187300 | AF6: 187300
A7: 43009 | B7: {=ROUND(C7/'variables - Table 1-1'!B6,0)} -> 2679 | C7: {=SUM(E7:J7)} -> 1663586 | D7: {=SUM(E7:G7)} -> 1316586 | E7: {=1101286} -> 1101286 | F7: 85916 | G7: {='net worth - retiro'!D9} -> 129384 | H7: {=80000+30000*3+45000+50000+2000+80000} -> 347000 | J7: 0 | K7: {=C7-N7} -> 948821.47 | L7: {=(K7/C7)} -> 0.57034711 | M7: {=N7-AF7} -> 592837.53 | N7: {=SUM(P7:AB7)} -> 714764.53 | P7: 133839 | Q7: 23640 | R7: 29410 | S7: 22084 | T7: 98252 | U7: 0 | V7: 120000 | W7: 85916 | X7: 172793 | AB7: 28830.533 | AC7: {=J6} -> 0 | AE7: 121927 | AF7: 121927
A8: 43040 | B8: {=ROUND(C8/'variables - Table 1-1'!B7,0)} -> 2215 | C8: {=SUM(E8:J8)} -> 1425860 | D8: {=SUM(E8:G8)} -> 1305860 | E8: {=1101355} -> 1101355 | F8: 81471 | G8: {='net worth - retiro'!D10} -> 123034 | H8: {=30000*4} -> 120000 | J8: 0 | K8: {=C8-N8} -> 656683.78 | L8: {=(K8/C8)} -> 0.46055278 | M8: {=N8-AF8} -> 546557.22 | N8: {=SUM(P8:AB8)} -> 769176.22 | P8: 163960 | Q8: 0 | R8: 29810 | S8: 24980 | T8: 86650 | U8: 0 | V8: 120000 | W8: 172471 | X8: 142498 | AB8: 28807.22 | AC8: {=J7} -> 0 | AE8: 222619 | AF8: 222619
A9: 43070 | B9: {=ROUND(C9/'variables - Table 1-1'!B8,0)} -> 2622 | C9: {=SUM(E9:J9)} -> 1610819 | D9: {=SUM(E9:G9)} -> 1305819 | E9: {=1101304} -> 1101304 | F9: 81471 | G9: {='net worth - retiro'!D11} -> 123044 | H9: {=80000*2+30000*3+50000+5000} -> 305000 | J9: 0 | K9: {=C9-N9} -> 803884.65 | L9: {=(K9/C9)} -> 0.49905337 | M9: {=N9-AF9} -> 683780.35 | N9: {=SUM(P9:AB9)} -> 806934.35 | P9: 193609 | Q9: 46215 | R9: 22470 | S9: 0 | T9: 124710 | U9: 0 | V9: 140000 | W9: 92461 | X9: 152373.35 | AB9: 35096 | AC9: {=J8} -> 0 | AE9: 123154 | AF9: 123154
A10: 43101 | B10: {=ROUND(C10/'variables - Table 1-1'!B9,0)} -> 2424 | C10: {=SUM(E10:J10)} -> 1470091 | D10: {=SUM(E10:G10)} -> 1310091 | E10: {=1101437} -> 1101437 | F10: 85916 | G10: {='net worth - retiro'!D12} -> 122738 | H10: {=40000+30000*4} -> 160000 | J10: 0 | K10: {=C10-N10} -> 707836 | L10: {=_xlfn.IFERROR(K10/C10,0)} -> 0.48149128 | M10: {=N10-AF10} -> 622726 | N10: {=SUM(P10:AB10)} -> 762255 | P10: 175665 | Q10: 0 | R10: 37460 | S10: 0 | T10: 151250 | U10: 0 | V10: 115000 | W10: 85916 | X10: 159203 | AB10: 37761 | AC10: {=J9} -> 0 | AE10: 139529 | AF10: 139529
A11: 43132 | B11: {=ROUND(C11/'variables - Table 1-1'!B10,0)} -> 2488 | C11: {=SUM(E11:J11)} -> 1471612 | D11: {=SUM(E11:G11)} -> 1301612 | E11: {=1103349} -> 1103349 | F11: 81638 | G11: {='net worth - retiro'!D13} -> 116625 | H11: {=80000+30000*3} -> 170000 | J11: 0 | K11: {=C11-N11} -> 471798 | L11: {=_xlfn.IFERROR(K11/C11,0)} -> 0.32059945 | M11: {=N11-AF11} -> 832114 | N11: {=SUM(P11:AB11)} -> 999814 | P11: 181799 | Q11: 69149 | R11: 42550 | S11: 208142 | T11: 122680 | U11: 0 | V11: 80000 | W11: 101638 | X11: 166188 | AB11: 27668 | AC11: {=J10} -> 0 | AE11: 167700 | AF11: 167700
A12: 43160 | B12: {=ROUND(C12/'variables - Table 1-1'!B11,0)} -> 3641 | C12: {=SUM(E12:J12)} -> 2196694 | D12: {=SUM(E12:G12)} -> 1301637 | E12: {=1103374} -> 1103374 | F12: 81638 | G12: {='net worth - retiro'!D14} -> 116625 | H12: {=650407+15000+80000+1520+2130+30000*3+AG12} -> 895057 | J12: 0 | K12: {=C12-N12} -> 1464675 | L12: {=_xlfn.IFERROR(K12/C12,0)} -> 0.66676333 | M12: {=N12-AE12} -> 432791 | N12: {=SUM(P12:AB12)} -> 732019 | P12: {=281859-4200} -> 277659 | Q12: 9955 | R12: 83320 | S12: 0 | T12: 88880 | U12: 0 | V12: 108000 | W12: 120828 | X12: 40328 | AB12: 3049 | AC12: {=J11} -> 0 | AE12: 299228 | AF12: 243228 | AG12: 56000
A13: 43191 | B13: {=ROUND(C13/'variables - Table 1-1'!B12,0)} -> 4606 | C13: {=SUM(E13:J13)} -> 2790130 | D13: {=SUM(E13:G13)} -> 1372630 | E13: 1200000 | F13: 81365 | G13: {='net worth - retiro'!D15} -> 91265 | H13: {=AG13+80000+30000*4+1200000} -> 1417500 | J13: 0 | K13: {=C13-N13} -> 2137545 | L13: {=_xlfn.IFERROR(K13/C13,0)} -> 0.76610946 | M13: {=N13-AE13} -> 525306 | N13: {=SUM(P13:AB13)} -> 652585 | P13: 181950 | Q13: 0 | R13: 29950 | S13: 0 | T13: 57180 | U13: 0 | V13: 153000 | W13: 131020 | X13: 66779 | AB13: 32706 | AC13: {=J12} -> 0 | AE13: 127279 | AF13: 109779 | AG13: 17500
A14: 43221 | B14: {=ROUND(C14/'variables - Table 1-1'!B13,0)} -> 1395 | C14: {=SUM(E14:J14)} -> 875062 | D14: {=SUM(E14:G14)-41314} -> 379592 | E14: {=304804} -> 304804 | F14: 81365 | G14: {='net worth - retiro'!D16} -> 34737 | H14: {=AG14+30000*4+25000-41314} -> 107186 | J14: {=346970} -> 346970 | K14: {=C14-N14} -> 234274 | L14: {=_xlfn.IFERROR(K14/C14,0)} -> 0.26772274 | M14: {=N14-AE14} -> 538265 | N14: {=SUM(P14:AB14)} -> 640788 | P14: 116288 | Q14: {=106245-13500-20274-10000} -> 62471 | R14: 16100 | S14: 0 | T14: 100800 | U14: 0 | V14: 150000 | W14: 85741 | X14: 54023 | AB14: {=55365} -> 55365 | AC14: {=J13} -> 0 | AE14: 102523 | AF14: 99023 | AG14: 3500
A15: 43252 | B15: {=ROUND(C15/'variables - Table 1-1'!B14,0)} -> 2553 | C15: {=SUM(E15:J15)} -> 1656689 | D15: {=SUM(E15:G15)} -> 1536689 | E15: {=1305231} -> 1305231 | F15: 81587 | G15: {='net worth - retiro'!D17} -> 149871 | H15: {=30000*4} -> 120000 | J15: 0 | K15: {=C15-N15} -> 595305 | L15: {=_xlfn.IFERROR(K15/C15,0)} -> 0.35933419 | M15: {=N15-AE15} -> 934243 | N15: {=SUM(P15:AC15)} -> 1061384 | P15: 172810 | Q15: 19077 | R15: 17780 | S15: 0 | T15: 59387 | U15: 0 | V15: 140000 | W15: 126587 | X15: 54141 | AB15: 124632 | AC15: 346970 | AE15: 127141 | AF15: 127141 | AG15: 15000
A16: 43282 | B16: {=ROUND(C16/'variables - Table 1-1'!B15,0)} -> 2643 | C16: {=SUM(E16:J16)} -> 1686766 | D16: {=SUM(E16:G16)} -> 1536766 | E16: {=1305308} -> 1305308 | F16: 81587 | G16: {='net worth - retiro'!D18} -> 149871 | H16: {=30000*5} -> 150000 | J16: 0 | K16: {=C16-N16} -> 898181 | L16: {=_xlfn.IFERROR(K16/C16,0)} -> 0.53248702 | M16: {=N16-AE16} -> 589898 | N16: {=SUM(P16:AC16)} -> 788585 | P16: 221983 | Q16: 30000 | R16: 3400 | S16: 0 | T16: 90928 | U16: 0 | V16: 200000 | W16: 161587 | X16: 48687 | AB16: 32000 | AC16: 0 | AE16: 198687 | AF16: 198687 | AG16: 15000
A17: 43313 | B17: {=ROUND(C17/'variables - Table 1-1'!B16,0)} -> 2453 | C17: {=SUM(E17:J17)} -> 1665468 | D17: {=SUM(E17:G17)} -> 1545468 | E17: 1313038 | F17: 81587 | G17: {='net worth - retiro'!D19} -> 150843 | H17: {=30000*4} -> 120000 | K17: {=C17-N17} -> 867592.48 | L17: {=_xlfn.IFERROR(K17/C17,0)} -> 0.52093014 | M17: {=N17-AE17} -> 582323.52 | N17: {=SUM(P17:AC17)} -> 797875.52 | P17: 155166 | Q17: 113683 | R17: 4830 | S17: 25492 | T17: 125980 | U17: 0 | V17: 200000 | W17: 83519.518 | X17: 57502 | AB17: 31703 | AC17: 0 | AE17: 215552 | AF17: 125502 | AG17: 90050
A18: 43344 | B18: {=ROUND(C18/'variables - Table 1-1'!B17,0)} -> 2570 | C18: {=SUM(E18:J18)} -> 1694404 | D18: {=SUM(E18:G18)} -> 1544404 | E18: 1307851 | F18: 85710 | G18: {='net worth - retiro'!D20} -> 150843 | H18: {=30000*(5-0)} -> 150000 | K18: {=C18-N18} -> 1108743.2 | L18: {=_xlfn.IFERROR(K18/C18,0)} -> 0.65435587 | M18: {=N18-AE18} -> 451097.8 | N18: {=SUM(P18:AC18)} -> 585660.8 | P18: {=199701} -> 199701 | Q18: 27153 | R18: 2550 | S18: 0 | T18: {=33230} -> 33230 | U18: 0 | V18: 190000 | W18: 85214.795 | X18: 43313 | AB18: 4499 | AC18: 0 | AE18: 134563 | AF18: 112563 | AG18: 22000
A19: 43374 | B19: {=ROUND(C19/'variables - Table 1-1'!B18,0)} -> 2921 | C19: {=SUM(E19:J19)} -> 2024160 | D19: {=SUM(E19:G19)} -> 1504160 | E19: 1271796 | F19: 85710 | G19: {='net worth - retiro'!D21} -> 146654 | H19: {=30000*4+400000} -> 520000 | K19: {=C19-N19} -> 1123636 | L19: {=_xlfn.IFERROR(K19/C19,0)} -> 0.55511224 | M19: {=N19-AE19} -> 733371 | N19: {=SUM(P19:X19,AC19)} -> 900524 | P19: 184544 | Q19: 84598 | R19: 17110 | S19: 0 | T19: 122405 | U19: 0 | V19: 150000 | W19: 102215 | X19: 239652 | AB19: 78349 | AC19: 0 | AE19: 167153 | AF19: 135488 | AG19: 31665
A20: 43405 | B20: {=ROUND(C20/'variables - Table 1-1'!B19,0)} -> 3617 | C20: {=SUM(E20:J20)} -> 2423722 | D20: {=SUM(E20:G20)} -> 2423722 | E20: 2123219 | F20: 85710 | G20: {='net worth - retiro'!D22} -> 214793 | H20: {=0} -> 0 | K20: {=C20-N20} -> 1326980 | L20: {=_xlfn.IFERROR(K20/C20,0)} -> 0.54749678 | M20: {=N20-AE20} -> 895905 | N20: {=SUM(P20:X20,AC20)} -> 1096742 | P20: 275472 | Q20: 19964 | R20: 6480 | S20: 94707 | T20: 302449 | U20: 0 | V20: 150000 | W20: 85812 | X20: 161858 | AB20: 155267 | AC20: 0 | AE20: 200837 | AF20: 153847 | AG20: 46990
A21: 43435 | B21: {=ROUND(C21/'variables - Table 1-1'!B20,0)} -> 3495 | C21: {=SUM(E21:J21)} -> 2423471 | D21: {=SUM(E21:G21)} -> 2423471 | E21: 2122179 | F21: 85710 | G21: {='net worth - retiro'!D23} -> 215582 | H21: {=0} -> 0 | K21: {=C21-N21} -> 1299768 | L21: {=_xlfn.IFERROR(K21/C21,0)} -> 0.53632497 | M21: {=N21-AE21} -> 803085 | N21: {=SUM(P21:X21,AC21)} -> 1123703 | P21: 214252 | Q21: 63190 | R21: 13330 | S21: 0 | T21: 395615 | U21: 0 | V21: 150000 | W21: 85710 | X21: 201606 | AB21: {=175209+1892} -> 177101 | AC21: 0 | AE21: {=SUM(AF21:AG21)} -> 320618 | AF21: 147582 | AG21: {=42341+130695} -> 173036
A22: 43466 | B22: {=ROUND(C22/'variables - Table 1-1'!B21,0)} -> 3654 | C22: {=SUM(E22:J22)} -> 2423745 | D22: {=SUM(E22:G22)} -> 2423745 | E22: 2122093 | F22: 85812 | G22: {='net worth - retiro'!D24} -> 215840 | H22: {=0} -> 0 | K22: {=C22-N22} -> 1724646 | L22: {=_xlfn.IFERROR(K22/C22,0)} -> 0.71156248 | M22: {=N22-AE22} -> 598716 | N22: {=SUM(P22:X22,AC22)} -> 699099 | P22: 209801 | Q22: 85298 | R22: 28530 | S22: 3766 | T22: 21400 | U22: 0 | V22: 155000 | W22: 85812 | X22: 109492 | AB22: 21855 | AC22: 0 | AE22: {=SUM(AF22:AG22)} -> 100383 | AF22: 100383 | AG22: {=0} -> 0
A23: 43497 | B23: {=ROUND(C23/'variables - Table 1-1'!B22,0)} -> 3739 | C23: {=SUM(E23:J23)} -> 2425605 | D23: {=SUM(E23:G23)} -> 2425605 | E23: 2122093 | F23: 85812 | G23: {='net worth - retiro'!D25} -> 217700 | H23: {=0} -> 0 | K23: {=C23-N23} -> 1609801 | L23: {=_xlfn.IFERROR(K23/C23,0)} -> 0.66366989 | M23: {=N23-AE23} -> 476001 | N23: {=SUM(P23:X23,AC23)} -> 815804 | P23: 269562 | Q23: 7000 | R23: 30378 | S23: 0 | T23: 114761 | U23: 0 | V23: 175000 | W23: 85751 | X23: 133352 | AB23: 31363 | AC23: 0 | AE23: {=SUM(AF23:AG23)} -> 339803 | AF23: 73647 | AG23: {=258656+7500} -> 266156
A24: 43525 | B24: {=ROUND(C24/'variables - Table 1-1'!B23,0)} -> 4285 | C24: {=SUM(E24:J24)} -> 2922564 | D24: {=SUM(E24:G24)} -> 2422564 | E24: 2119052 | F24: 85812 | G24: {='net worth - retiro'!D26} -> 217700 | H24: {=500000} -> 500000 | K24: {=C24-N24} -> 1831316 | L24: {=_xlfn.IFERROR(K24/C24,0)} -> 0.6266128 | M24: {=N24-AE24} -> 982015 | N24: {=SUM(P24:X24,AC24)} -> 1091248 | P24: 196890 | Q24: 42700 | R24: 35890 | S24: 0 | T24: 235969 | U24: 0 | V24: 185000 | W24: 104791 | X24: 290008 | AB24: 159759 | AC24: 0 | AE24: 109233 | AF24: 109233 | AG24: 0
A25: 43556 | B25: {=ROUND(C25/'variables - Table 1-1'!B24,0)} -> 3584 | C25: {=SUM(E25:J25)} -> 2430374 | D25: {=SUM(E25:G25)} -> 2430374 | E25: 2122917 | F25: 89242 | G25: {='net worth - retiro'!D27} -> 218215 | H25: {=0} -> 0 | K25: {=C25-N25} -> 1251325 | L25: {=_xlfn.IFERROR(K25/C25,0)} -> 0.51486932 | M25: {=N25-AE25} -> 872926.5 | N25: {=SUM(P25:X25,AC25)} -> 1179049 | P25: 131925 | Q25: 48881 | R25: 72787.5 | S25: 0 | T25: 412926.5 | U25: 0 | V25: 150000 | W25: 85812 | X25: 276717 | AB25: 309234 | AC25: 0 | AE25: 306122.5 | AF25: 75712 | AG25: 230410.5
A26: 43586 | B26: {=ROUND(C26/'variables - Table 1-1'!B25,0)} -> 3425 | C26: {=SUM(E26:J26)} -> 2430374 | D26: {=SUM(E26:G26)} -> 2430374 | E26: 2122917 | F26: 89242 | G26: {='net worth - retiro'!D28} -> 218215 | H26: {=0} -> 0 | K26: {=C26-N26} -> 1108602 | L26: {=_xlfn.IFERROR(K26/C26,0)} -> 0.45614461 | M26: {=N26-AE26} -> 1029852 | N26: {=SUM(P26:X26,AC26)} -> 1321772 | P26: 116929 | Q26: 135579 | R26: 80939 | S26: 89980 | T26: 494540 | U26: 0 | V26: 180000 | W26: 86425 | X26: 137380 | AB26: {='flujos - Gasto mes actual'!AN$37} -> 0 | AC26: 0 | AE26: {=SUM(AF26:AG26)} -> 291920 | AF26: 87000 | AG26: 204920
A27: 43617 | B27: {=ROUND(C27/'variables - Table 1-1'!B26,0)} -> 3574 | C27: {=SUM(E27:J27)} -> 2430795 | D27: {=SUM(E27:G27)} -> 2430795 | E27: 2123338 | F27: 89242 | G27: {='net worth - retiro'!D29} -> 218215 | H27: {=0} -> 0 | K27: {=C27-N27} -> 1214653 | L27: {=_xlfn.IFERROR(K27/C27,0)} -> 0.49969372 | M27: {=N27-AE27} -> 1050954 | N27: {=SUM(P27:X27,AC27)} -> 1216142 | P27: 254415 | Q27: {=10000+65000+50000} -> 125000 | R27: 64789 | S27: 0 | T27: 352474 | U27: 0 | V27: 180000 | W27: 97417 | X27: 142047 | AB27: 219952 | AC27: 0 | AE27: {=SUM(AF27:AG27)} -> 165188 | AF27: 126347 | AG27: 38841
A28: 43647 | B28: {=ROUND(C28/'variables - Table 1-1'!B27,0)} -> 3478 | C28: {=SUM(E28:J28)} -> 2430795 | D28: {=SUM(E28:G28)} -> 2430795 | E28: 2123338 | F28: 89242 | G28: {='net worth - retiro'!D30} -> 218215 | H28: {=0} -> 0 | K28: {=C28-N28} -> -1204880 | L28: {=_xlfn.IFERROR(K28/C28,0)} -> -0.49567323 | M28: {=N28-AE28} -> 3542249 | N28: {=SUM(P28:X28,AC28)} -> 3635675 | P28: 401423 | Q28: 11790 | R28: 81516 | S28: 0 | T28: 1788124 | U28: 1000000 | V28: 155000 | W28: 136198 | X28: 61624 | Y28: 30000 | Z28: 10000 | AA28: 80000 | AB28: 170771 | AC28: 0 | AE28: {=SUM(AF28:AG28)} -> 93426 | AF28: 33000 | AG28: 60426 | AH28: 2165000
A29: 43678 | B29: {=ROUND(C29/'variables - Table 1-1'!B28,0)} -> 4150 | C29: {=SUM(E29:J29)} -> 2991383 | D29: {=SUM(E29:G29)} -> 2431557 | E29: {=2124100} -> 2124100 | F29: 89242 | G29: {='net worth - retiro'!D31} -> 218215 | H29: {='net worth - cash and cash equiv'!D31} -> 559826 | K29: {=C29-N29} -> 902538 | L29: {=_xlfn.IFERROR(K29/C29,0)} -> 0.30171262 | M29: {=N29-AE29} -> 2020772 | N29: {=SUM(P29:X29,AC29)} -> 2088845 | P29: 360634 | Q29: 75004 | R29: 39540 | S29: 0 | T29: 305569 | U29: 746875 | V29: 300000 | W29: 166124 | X29: 95099 | Y29: 5083 | Z29: 41640 | AA29: 21089 | AB29: 56983 | AC29: 0 | AE29: 68073 | AF29: 30073 | AG29: 38000 | AH29: 370400
